Internal Server Error: /
Traceback (most recent call last):
  File "/Library/Frameworks/Python.framework/Versions/3.12/lib/python3.12/site-packages/django/core/handlers/exception.py", line 55, in inner
    response = get_response(request)
               ^^^^^^^^^^^^^^^^^^^^^
  File "/Library/Frameworks/Python.framework/Versions/3.12/lib/python3.12/site-packages/django/core/handlers/base.py", line 197, in _get_response
    response = wrapped_callback(request, *callback_args, **callback_kwargs)
               ^^^^^^^^^^^^^^^^^^^^^^^^^^^^^^^^^^^^^^^^^^^^^^^^^^^^^^^^^^^^
  File "/Users/gwenaellebousses/Desktop/1-Developpement/1-CEF/Niveau3/Module2/mediatheque/mediatheque/authentication/views.py", line 27, in user_login
    return redirect("user_home")
           ^^^^^^^^^^^^^^^^^^^^^
  File "/Library/Frameworks/Python.framework/Versions/3.12/lib/python3.12/site-packages/django/shortcuts.py", line 48, in redirect
    return redirect_class(resolve_url(to, *args, **kwargs))
                          ^^^^^^^^^^^^^^^^^^^^^^^^^^^^^^^^
  File "/Library/Frameworks/Python.framework/Versions/3.12/lib/python3.12/site-packages/django/shortcuts.py", line 179, in resolve_url
    return reverse(to, args=args, kwargs=kwargs)
           ^^^^^^^^^^^^^^^^^^^^^^^^^^^^^^^^^^^^^
  File "/Library/Frameworks/Python.framework/Versions/3.12/lib/python3.12/site-packages/django/urls/base.py", line 88, in reverse
    return resolver._reverse_with_prefix(view, prefix, *args, **kwargs)
           ^^^^^^^^^^^^^^^^^^^^^^^^^^^^^^^^^^^^^^^^^^^^^^^^^^^^^^^^^^^^
  File "/Library/Frameworks/Python.framework/Versions/3.12/lib/python3.12/site-packages/django/urls/resolvers.py", line 848, in _reverse_with_prefix
    raise NoReverseMatch(msg)
django.urls.exceptions.NoReverseMatch: Reverse for 'user_home' not found. 'user_home' is not a valid view function or pattern name.
Not Found: /media/home
Not Found: /accounts/login/
Not Found: /accounts/login/
Internal Server Error: /media/media/
Traceback (most recent call last):
  File "/Library/Frameworks/Python.framework/Versions/3.12/lib/python3.12/site-packages/django/db/backends/utils.py", line 105, in _execute
    return self.cursor.execute(sql, params)
           ^^^^^^^^^^^^^^^^^^^^^^^^^^^^^^^^
  File "/Library/Frameworks/Python.framework/Versions/3.12/lib/python3.12/site-packages/django/db/backends/sqlite3/base.py", line 328, in execute
    return super().execute(query, params)
           ^^^^^^^^^^^^^^^^^^^^^^^^^^^^^^
sqlite3.OperationalError: no such table: users_libraryuser

The above exception was the direct cause of the following exception:

Traceback (most recent call last):
  File "/Library/Frameworks/Python.framework/Versions/3.12/lib/python3.12/site-packages/django/core/handlers/exception.py", line 55, in inner
    response = get_response(request)
               ^^^^^^^^^^^^^^^^^^^^^
  File "/Library/Frameworks/Python.framework/Versions/3.12/lib/python3.12/site-packages/django/core/handlers/base.py", line 197, in _get_response
    response = wrapped_callback(request, *callback_args, **callback_kwargs)
               ^^^^^^^^^^^^^^^^^^^^^^^^^^^^^^^^^^^^^^^^^^^^^^^^^^^^^^^^^^^^
  File "/Library/Frameworks/Python.framework/Versions/3.12/lib/python3.12/site-packages/django/contrib/auth/decorators.py", line 22, in _wrapper_view
    if test_func(request.user):
       ^^^^^^^^^^^^^^^^^^^^^^^
  File "/Library/Frameworks/Python.framework/Versions/3.12/lib/python3.12/site-packages/django/contrib/auth/decorators.py", line 51, in <lambda>
    lambda u: u.is_authenticated,
              ^^^^^^^^^^^^^^^^^^
  File "/Library/Frameworks/Python.framework/Versions/3.12/lib/python3.12/site-packages/django/utils/functional.py", line 251, in inner
    self._setup()
  File "/Library/Frameworks/Python.framework/Versions/3.12/lib/python3.12/site-packages/django/utils/functional.py", line 404, in _setup
    self._wrapped = self._setupfunc()
                    ^^^^^^^^^^^^^^^^^
  File "/Library/Frameworks/Python.framework/Versions/3.12/lib/python3.12/site-packages/django/contrib/auth/middleware.py", line 33, in <lambda>
    request.user = SimpleLazyObject(lambda: get_user(request))
                                            ^^^^^^^^^^^^^^^^^
  File "/Library/Frameworks/Python.framework/Versions/3.12/lib/python3.12/site-packages/django/contrib/auth/middleware.py", line 13, in get_user
    request._cached_user = auth.get_user(request)
                           ^^^^^^^^^^^^^^^^^^^^^^
  File "/Library/Frameworks/Python.framework/Versions/3.12/lib/python3.12/site-packages/django/contrib/auth/__init__.py", line 216, in get_user
    user = backend.get_user(user_id)
           ^^^^^^^^^^^^^^^^^^^^^^^^^
  File "/Library/Frameworks/Python.framework/Versions/3.12/lib/python3.12/site-packages/django/contrib/auth/backends.py", line 157, in get_user
    user = UserModel._default_manager.get(pk=user_id)
           ^^^^^^^^^^^^^^^^^^^^^^^^^^^^^^^^^^^^^^^^^^
  File "/Library/Frameworks/Python.framework/Versions/3.12/lib/python3.12/site-packages/django/db/models/manager.py", line 87, in manager_method
    return getattr(self.get_queryset(), name)(*args, **kwargs)
           ^^^^^^^^^^^^^^^^^^^^^^^^^^^^^^^^^^^^^^^^^^^^^^^^^^^
  File "/Library/Frameworks/Python.framework/Versions/3.12/lib/python3.12/site-packages/django/db/models/query.py", line 643, in get
    num = len(clone)
          ^^^^^^^^^^
  File "/Library/Frameworks/Python.framework/Versions/3.12/lib/python3.12/site-packages/django/db/models/query.py", line 380, in __len__
    self._fetch_all()
  File "/Library/Frameworks/Python.framework/Versions/3.12/lib/python3.12/site-packages/django/db/models/query.py", line 1926, in _fetch_all
    self._result_cache = list(self._iterable_class(self))
                         ^^^^^^^^^^^^^^^^^^^^^^^^^^^^^^^^
  File "/Library/Frameworks/Python.framework/Versions/3.12/lib/python3.12/site-packages/django/db/models/query.py", line 91, in __iter__
    results = compiler.execute_sql(
              ^^^^^^^^^^^^^^^^^^^^^
  File "/Library/Frameworks/Python.framework/Versions/3.12/lib/python3.12/site-packages/django/db/models/sql/compiler.py", line 1562, in execute_sql
    cursor.execute(sql, params)
  File "/Library/Frameworks/Python.framework/Versions/3.12/lib/python3.12/site-packages/django/db/backends/utils.py", line 122, in execute
    return super().execute(sql, params)
           ^^^^^^^^^^^^^^^^^^^^^^^^^^^^
  File "/Library/Frameworks/Python.framework/Versions/3.12/lib/python3.12/site-packages/django/db/backends/utils.py", line 79, in execute
    return self._execute_with_wrappers(
           ^^^^^^^^^^^^^^^^^^^^^^^^^^^^
  File "/Library/Frameworks/Python.framework/Versions/3.12/lib/python3.12/site-packages/django/db/backends/utils.py", line 92, in _execute_with_wrappers
    return executor(sql, params, many, context)
           ^^^^^^^^^^^^^^^^^^^^^^^^^^^^^^^^^^^^
  File "/Library/Frameworks/Python.framework/Versions/3.12/lib/python3.12/site-packages/django/db/backends/utils.py", line 100, in _execute
    with self.db.wrap_database_errors:
  File "/Library/Frameworks/Python.framework/Versions/3.12/lib/python3.12/site-packages/django/db/utils.py", line 91, in __exit__
    raise dj_exc_value.with_traceback(traceback) from exc_value
  File "/Library/Frameworks/Python.framework/Versions/3.12/lib/python3.12/site-packages/django/db/backends/utils.py", line 105, in _execute
    return self.cursor.execute(sql, params)
           ^^^^^^^^^^^^^^^^^^^^^^^^^^^^^^^^
  File "/Library/Frameworks/Python.framework/Versions/3.12/lib/python3.12/site-packages/django/db/backends/sqlite3/base.py", line 328, in execute
    return super().execute(query, params)
           ^^^^^^^^^^^^^^^^^^^^^^^^^^^^^^
django.db.utils.OperationalError: no such table: users_libraryuser
Not Found: /favicon.ico
Not Found: /admimn
Not Found: /media/livre_update/6/
Not Found: /media/livre_update/6/
Not Found: /media/livre_update/6/
Not Found: /media/livre_update/6/
Not Found: /media/livre_update/6/
Not Found: /media/livre_update/6/
Not Found: /media/livre_update/6/
Not Found: /media/livre_update/5/
Internal Server Error: /media/media/
Traceback (most recent call last):
  File "/Library/Frameworks/Python.framework/Versions/3.12/lib/python3.12/site-packages/django/core/handlers/exception.py", line 55, in inner
    response = get_response(request)
               ^^^^^^^^^^^^^^^^^^^^^
  File "/Library/Frameworks/Python.framework/Versions/3.12/lib/python3.12/site-packages/django/core/handlers/base.py", line 197, in _get_response
    response = wrapped_callback(request, *callback_args, **callback_kwargs)
               ^^^^^^^^^^^^^^^^^^^^^^^^^^^^^^^^^^^^^^^^^^^^^^^^^^^^^^^^^^^^
  File "/Library/Frameworks/Python.framework/Versions/3.12/lib/python3.12/site-packages/django/contrib/auth/decorators.py", line 23, in _wrapper_view
    return view_func(request, *args, **kwargs)
           ^^^^^^^^^^^^^^^^^^^^^^^^^^^^^^^^^^^
  File "/Library/Frameworks/Python.framework/Versions/3.12/lib/python3.12/site-packages/django/contrib/auth/decorators.py", line 23, in _wrapper_view
    return view_func(request, *args, **kwargs)
           ^^^^^^^^^^^^^^^^^^^^^^^^^^^^^^^^^^^
  File "/Users/gwenaellebousses/Desktop/1-Developpement/1-CEF/Niveau3/Module2/mediatheque/mediatheque/media/views.py", line 34, in media
    return render(
           ^^^^^^^
  File "/Library/Frameworks/Python.framework/Versions/3.12/lib/python3.12/site-packages/django/shortcuts.py", line 24, in render
    content = loader.render_to_string(template_name, context, request, using=using)
              ^^^^^^^^^^^^^^^^^^^^^^^^^^^^^^^^^^^^^^^^^^^^^^^^^^^^^^^^^^^^^^^^^^^^^
  File "/Library/Frameworks/Python.framework/Versions/3.12/lib/python3.12/site-packages/django/template/loader.py", line 62, in render_to_string
    return template.render(context, request)
           ^^^^^^^^^^^^^^^^^^^^^^^^^^^^^^^^^
  File "/Library/Frameworks/Python.framework/Versions/3.12/lib/python3.12/site-packages/django/template/backends/django.py", line 61, in render
    return self.template.render(context)
           ^^^^^^^^^^^^^^^^^^^^^^^^^^^^^
  File "/Library/Frameworks/Python.framework/Versions/3.12/lib/python3.12/site-packages/django/template/base.py", line 171, in render
    return self._render(context)
           ^^^^^^^^^^^^^^^^^^^^^
  File "/Library/Frameworks/Python.framework/Versions/3.12/lib/python3.12/site-packages/django/template/base.py", line 163, in _render
    return self.nodelist.render(context)
           ^^^^^^^^^^^^^^^^^^^^^^^^^^^^^
  File "/Library/Frameworks/Python.framework/Versions/3.12/lib/python3.12/site-packages/django/template/base.py", line 1000, in render
    return SafeString("".join([node.render_annotated(context) for node in self]))
                               ^^^^^^^^^^^^^^^^^^^^^^^^^^^^^^
  File "/Library/Frameworks/Python.framework/Versions/3.12/lib/python3.12/site-packages/django/template/base.py", line 961, in render_annotated
    return self.render(context)
           ^^^^^^^^^^^^^^^^^^^^
  File "/Library/Frameworks/Python.framework/Versions/3.12/lib/python3.12/site-packages/django/template/defaulttags.py", line 241, in render
    nodelist.append(node.render_annotated(context))
                    ^^^^^^^^^^^^^^^^^^^^^^^^^^^^^^
  File "/Library/Frameworks/Python.framework/Versions/3.12/lib/python3.12/site-packages/django/template/base.py", line 961, in render_annotated
    return self.render(context)
           ^^^^^^^^^^^^^^^^^^^^
  File "/Library/Frameworks/Python.framework/Versions/3.12/lib/python3.12/site-packages/django/template/defaulttags.py", line 478, in render
    url = reverse(view_name, args=args, kwargs=kwargs, current_app=current_app)
          ^^^^^^^^^^^^^^^^^^^^^^^^^^^^^^^^^^^^^^^^^^^^^^^^^^^^^^^^^^^^^^^^^^^^^
  File "/Library/Frameworks/Python.framework/Versions/3.12/lib/python3.12/site-packages/django/urls/base.py", line 88, in reverse
    return resolver._reverse_with_prefix(view, prefix, *args, **kwargs)
           ^^^^^^^^^^^^^^^^^^^^^^^^^^^^^^^^^^^^^^^^^^^^^^^^^^^^^^^^^^^^
  File "/Library/Frameworks/Python.framework/Versions/3.12/lib/python3.12/site-packages/django/urls/resolvers.py", line 848, in _reverse_with_prefix
    raise NoReverseMatch(msg)
django.urls.exceptions.NoReverseMatch: Reverse for 'media_update' not found. 'media_update' is not a valid view function or pattern name.
Internal Server Error: /media/media/
Traceback (most recent call last):
  File "/Library/Frameworks/Python.framework/Versions/3.12/lib/python3.12/site-packages/django/core/handlers/exception.py", line 55, in inner
    response = get_response(request)
               ^^^^^^^^^^^^^^^^^^^^^
  File "/Library/Frameworks/Python.framework/Versions/3.12/lib/python3.12/site-packages/django/core/handlers/base.py", line 197, in _get_response
    response = wrapped_callback(request, *callback_args, **callback_kwargs)
               ^^^^^^^^^^^^^^^^^^^^^^^^^^^^^^^^^^^^^^^^^^^^^^^^^^^^^^^^^^^^
  File "/Library/Frameworks/Python.framework/Versions/3.12/lib/python3.12/site-packages/django/contrib/auth/decorators.py", line 23, in _wrapper_view
    return view_func(request, *args, **kwargs)
           ^^^^^^^^^^^^^^^^^^^^^^^^^^^^^^^^^^^
  File "/Library/Frameworks/Python.framework/Versions/3.12/lib/python3.12/site-packages/django/contrib/auth/decorators.py", line 23, in _wrapper_view
    return view_func(request, *args, **kwargs)
           ^^^^^^^^^^^^^^^^^^^^^^^^^^^^^^^^^^^
  File "/Users/gwenaellebousses/Desktop/1-Developpement/1-CEF/Niveau3/Module2/mediatheque/mediatheque/media/views.py", line 34, in media
    return render(
           ^^^^^^^
  File "/Library/Frameworks/Python.framework/Versions/3.12/lib/python3.12/site-packages/django/shortcuts.py", line 24, in render
    content = loader.render_to_string(template_name, context, request, using=using)
              ^^^^^^^^^^^^^^^^^^^^^^^^^^^^^^^^^^^^^^^^^^^^^^^^^^^^^^^^^^^^^^^^^^^^^
  File "/Library/Frameworks/Python.framework/Versions/3.12/lib/python3.12/site-packages/django/template/loader.py", line 62, in render_to_string
    return template.render(context, request)
           ^^^^^^^^^^^^^^^^^^^^^^^^^^^^^^^^^
  File "/Library/Frameworks/Python.framework/Versions/3.12/lib/python3.12/site-packages/django/template/backends/django.py", line 61, in render
    return self.template.render(context)
           ^^^^^^^^^^^^^^^^^^^^^^^^^^^^^
  File "/Library/Frameworks/Python.framework/Versions/3.12/lib/python3.12/site-packages/django/template/base.py", line 171, in render
    return self._render(context)
           ^^^^^^^^^^^^^^^^^^^^^
  File "/Library/Frameworks/Python.framework/Versions/3.12/lib/python3.12/site-packages/django/template/base.py", line 163, in _render
    return self.nodelist.render(context)
           ^^^^^^^^^^^^^^^^^^^^^^^^^^^^^
  File "/Library/Frameworks/Python.framework/Versions/3.12/lib/python3.12/site-packages/django/template/base.py", line 1000, in render
    return SafeString("".join([node.render_annotated(context) for node in self]))
                               ^^^^^^^^^^^^^^^^^^^^^^^^^^^^^^
  File "/Library/Frameworks/Python.framework/Versions/3.12/lib/python3.12/site-packages/django/template/base.py", line 961, in render_annotated
    return self.render(context)
           ^^^^^^^^^^^^^^^^^^^^
  File "/Library/Frameworks/Python.framework/Versions/3.12/lib/python3.12/site-packages/django/template/defaulttags.py", line 241, in render
    nodelist.append(node.render_annotated(context))
                    ^^^^^^^^^^^^^^^^^^^^^^^^^^^^^^
  File "/Library/Frameworks/Python.framework/Versions/3.12/lib/python3.12/site-packages/django/template/base.py", line 961, in render_annotated
    return self.render(context)
           ^^^^^^^^^^^^^^^^^^^^
  File "/Library/Frameworks/Python.framework/Versions/3.12/lib/python3.12/site-packages/django/template/defaulttags.py", line 478, in render
    url = reverse(view_name, args=args, kwargs=kwargs, current_app=current_app)
          ^^^^^^^^^^^^^^^^^^^^^^^^^^^^^^^^^^^^^^^^^^^^^^^^^^^^^^^^^^^^^^^^^^^^^
  File "/Library/Frameworks/Python.framework/Versions/3.12/lib/python3.12/site-packages/django/urls/base.py", line 88, in reverse
    return resolver._reverse_with_prefix(view, prefix, *args, **kwargs)
           ^^^^^^^^^^^^^^^^^^^^^^^^^^^^^^^^^^^^^^^^^^^^^^^^^^^^^^^^^^^^
  File "/Library/Frameworks/Python.framework/Versions/3.12/lib/python3.12/site-packages/django/urls/resolvers.py", line 848, in _reverse_with_prefix
    raise NoReverseMatch(msg)
django.urls.exceptions.NoReverseMatch: Reverse for 'media_update' not found. 'media_update' is not a valid view function or pattern name.
Internal Server Error: /media/book_update/5/
Traceback (most recent call last):
  File "/Library/Frameworks/Python.framework/Versions/3.12/lib/python3.12/site-packages/django/core/handlers/exception.py", line 55, in inner
    response = get_response(request)
               ^^^^^^^^^^^^^^^^^^^^^
  File "/Library/Frameworks/Python.framework/Versions/3.12/lib/python3.12/site-packages/django/core/handlers/base.py", line 197, in _get_response
    response = wrapped_callback(request, *callback_args, **callback_kwargs)
               ^^^^^^^^^^^^^^^^^^^^^^^^^^^^^^^^^^^^^^^^^^^^^^^^^^^^^^^^^^^^
  File "/Library/Frameworks/Python.framework/Versions/3.12/lib/python3.12/site-packages/django/contrib/auth/decorators.py", line 23, in _wrapper_view
    return view_func(request, *args, **kwargs)
           ^^^^^^^^^^^^^^^^^^^^^^^^^^^^^^^^^^^
  File "/Library/Frameworks/Python.framework/Versions/3.12/lib/python3.12/site-packages/django/contrib/auth/decorators.py", line 23, in _wrapper_view
    return view_func(request, *args, **kwargs)
           ^^^^^^^^^^^^^^^^^^^^^^^^^^^^^^^^^^^
  File "/Users/gwenaellebousses/Desktop/1-Developpement/1-CEF/Niveau3/Module2/mediatheque/mediatheque/media/views.py", line 118, in book_update
    form = BookForm(instance=media)
           ^^^^^^^^^^^^^^^^^^^^^^^^
  File "/Library/Frameworks/Python.framework/Versions/3.12/lib/python3.12/site-packages/django/forms/models.py", line 366, in __init__
    object_data = model_to_dict(instance, opts.fields, opts.exclude)
                  ^^^^^^^^^^^^^^^^^^^^^^^^^^^^^^^^^^^^^^^^^^^^^^^^^^
  File "/Library/Frameworks/Python.framework/Versions/3.12/lib/python3.12/site-packages/django/forms/models.py", line 107, in model_to_dict
    opts = instance._meta
           ^^^^^^^^^^^^^^
AttributeError: 'function' object has no attribute '_meta'
Internal Server Error: /media/book_update/5/
Traceback (most recent call last):
  File "/Library/Frameworks/Python.framework/Versions/3.12/lib/python3.12/site-packages/django/core/handlers/exception.py", line 55, in inner
    response = get_response(request)
               ^^^^^^^^^^^^^^^^^^^^^
  File "/Library/Frameworks/Python.framework/Versions/3.12/lib/python3.12/site-packages/django/core/handlers/base.py", line 197, in _get_response
    response = wrapped_callback(request, *callback_args, **callback_kwargs)
               ^^^^^^^^^^^^^^^^^^^^^^^^^^^^^^^^^^^^^^^^^^^^^^^^^^^^^^^^^^^^
  File "/Library/Frameworks/Python.framework/Versions/3.12/lib/python3.12/site-packages/django/contrib/auth/decorators.py", line 23, in _wrapper_view
    return view_func(request, *args, **kwargs)
           ^^^^^^^^^^^^^^^^^^^^^^^^^^^^^^^^^^^
  File "/Library/Frameworks/Python.framework/Versions/3.12/lib/python3.12/site-packages/django/contrib/auth/decorators.py", line 23, in _wrapper_view
    return view_func(request, *args, **kwargs)
           ^^^^^^^^^^^^^^^^^^^^^^^^^^^^^^^^^^^
  File "/Users/gwenaellebousses/Desktop/1-Developpement/1-CEF/Niveau3/Module2/mediatheque/mediatheque/media/views.py", line 116, in book_update
    return redirect("media_detail", media.id)
                                    ^^^^^^^^
AttributeError: 'function' object has no attribute 'id'
Not Found: /accounts/login/
Not Found: /accounts/login/
Not Found: /accounts/login/
Internal Server Error: /user/users.home/
Traceback (most recent call last):
  File "/Library/Frameworks/Python.framework/Versions/3.12/lib/python3.12/site-packages/django/core/handlers/exception.py", line 55, in inner
    response = get_response(request)
               ^^^^^^^^^^^^^^^^^^^^^
  File "/Library/Frameworks/Python.framework/Versions/3.12/lib/python3.12/site-packages/django/core/handlers/base.py", line 197, in _get_response
    response = wrapped_callback(request, *callback_args, **callback_kwargs)
               ^^^^^^^^^^^^^^^^^^^^^^^^^^^^^^^^^^^^^^^^^^^^^^^^^^^^^^^^^^^^
  File "/Library/Frameworks/Python.framework/Versions/3.12/lib/python3.12/site-packages/django/contrib/auth/decorators.py", line 23, in _wrapper_view
    return view_func(request, *args, **kwargs)
           ^^^^^^^^^^^^^^^^^^^^^^^^^^^^^^^^^^^
  File "/Users/gwenaellebousses/Desktop/1-Developpement/1-CEF/Niveau3/Module2/mediatheque-2/mediatheque/users/views.py", line 71, in home
    return render(
           ^^^^^^^
  File "/Library/Frameworks/Python.framework/Versions/3.12/lib/python3.12/site-packages/django/shortcuts.py", line 24, in render
    content = loader.render_to_string(template_name, context, request, using=using)
              ^^^^^^^^^^^^^^^^^^^^^^^^^^^^^^^^^^^^^^^^^^^^^^^^^^^^^^^^^^^^^^^^^^^^^
  File "/Library/Frameworks/Python.framework/Versions/3.12/lib/python3.12/site-packages/django/template/loader.py", line 61, in render_to_string
    template = get_template(template_name, using=using)
               ^^^^^^^^^^^^^^^^^^^^^^^^^^^^^^^^^^^^^^^^
  File "/Library/Frameworks/Python.framework/Versions/3.12/lib/python3.12/site-packages/django/template/loader.py", line 19, in get_template
    raise TemplateDoesNotExist(template_name, chain=chain)
django.template.exceptions.TemplateDoesNotExist: users/home.html
Internal Server Error: /user/users/home/
Traceback (most recent call last):
  File "/Library/Frameworks/Python.framework/Versions/3.12/lib/python3.12/site-packages/django/core/handlers/exception.py", line 55, in inner
    response = get_response(request)
               ^^^^^^^^^^^^^^^^^^^^^
  File "/Library/Frameworks/Python.framework/Versions/3.12/lib/python3.12/site-packages/django/core/handlers/base.py", line 197, in _get_response
    response = wrapped_callback(request, *callback_args, **callback_kwargs)
               ^^^^^^^^^^^^^^^^^^^^^^^^^^^^^^^^^^^^^^^^^^^^^^^^^^^^^^^^^^^^
  File "/Library/Frameworks/Python.framework/Versions/3.12/lib/python3.12/site-packages/django/contrib/auth/decorators.py", line 23, in _wrapper_view
    return view_func(request, *args, **kwargs)
           ^^^^^^^^^^^^^^^^^^^^^^^^^^^^^^^^^^^
  File "/Users/gwenaellebousses/Desktop/1-Developpement/1-CEF/Niveau3/Module2/mediatheque-2/mediatheque/users/views.py", line 71, in home
    return render(
           ^^^^^^^
  File "/Library/Frameworks/Python.framework/Versions/3.12/lib/python3.12/site-packages/django/shortcuts.py", line 24, in render
    content = loader.render_to_string(template_name, context, request, using=using)
              ^^^^^^^^^^^^^^^^^^^^^^^^^^^^^^^^^^^^^^^^^^^^^^^^^^^^^^^^^^^^^^^^^^^^^
  File "/Library/Frameworks/Python.framework/Versions/3.12/lib/python3.12/site-packages/django/template/loader.py", line 61, in render_to_string
    template = get_template(template_name, using=using)
               ^^^^^^^^^^^^^^^^^^^^^^^^^^^^^^^^^^^^^^^^
  File "/Library/Frameworks/Python.framework/Versions/3.12/lib/python3.12/site-packages/django/template/loader.py", line 19, in get_template
    raise TemplateDoesNotExist(template_name, chain=chain)
django.template.exceptions.TemplateDoesNotExist: users/home.html
Internal Server Error: /user/users/home/
Traceback (most recent call last):
  File "/Library/Frameworks/Python.framework/Versions/3.12/lib/python3.12/site-packages/django/core/handlers/exception.py", line 55, in inner
    response = get_response(request)
               ^^^^^^^^^^^^^^^^^^^^^
  File "/Library/Frameworks/Python.framework/Versions/3.12/lib/python3.12/site-packages/django/core/handlers/base.py", line 197, in _get_response
    response = wrapped_callback(request, *callback_args, **callback_kwargs)
               ^^^^^^^^^^^^^^^^^^^^^^^^^^^^^^^^^^^^^^^^^^^^^^^^^^^^^^^^^^^^
  File "/Library/Frameworks/Python.framework/Versions/3.12/lib/python3.12/site-packages/django/contrib/auth/decorators.py", line 23, in _wrapper_view
    return view_func(request, *args, **kwargs)
           ^^^^^^^^^^^^^^^^^^^^^^^^^^^^^^^^^^^
  File "/Users/gwenaellebousses/Desktop/1-Developpement/1-CEF/Niveau3/Module2/mediatheque-2/mediatheque/users/views.py", line 71, in home
    return render(
           ^^^^^^^
  File "/Library/Frameworks/Python.framework/Versions/3.12/lib/python3.12/site-packages/django/shortcuts.py", line 24, in render
    content = loader.render_to_string(template_name, context, request, using=using)
              ^^^^^^^^^^^^^^^^^^^^^^^^^^^^^^^^^^^^^^^^^^^^^^^^^^^^^^^^^^^^^^^^^^^^^
  File "/Library/Frameworks/Python.framework/Versions/3.12/lib/python3.12/site-packages/django/template/loader.py", line 61, in render_to_string
    template = get_template(template_name, using=using)
               ^^^^^^^^^^^^^^^^^^^^^^^^^^^^^^^^^^^^^^^^
  File "/Library/Frameworks/Python.framework/Versions/3.12/lib/python3.12/site-packages/django/template/loader.py", line 19, in get_template
    raise TemplateDoesNotExist(template_name, chain=chain)
django.template.exceptions.TemplateDoesNotExist: users/user-home.html
Not Found: /accounts/login/
Not Found: /accounts/login/
